<?xml version="1.0" ?>

<robot name="drone">
  <link name="base_link">
    <visual>
    <geometry>
    <box size="0.4 0.1 0.1"/>
    </geometry>
    </visual>
  </link>

  <link name="arm_1">
    <visual>
    <geometry>
    <box size="0.6 0.2 0.2"/>
    </geometry>
    </visual>
  </link>

  <joint name="b_arm_1" type="fixed">
    <parent link="base_link" />
    <child link="arm_1" />
  </joint>

  <link name="arm_2">
    <visual>
    <geometry>
    <box size="0.6 0.2 0.3"/>
    </geometry>
    </visual>
  </link>

  <joint name="b_arm_2" type="fixed">
    <parent link="base_link" />
    <child link="arm_2" />
  </joint>

  <link name="arm_3">
    <visual>
    <geometry>
    <box size="0.6 0.2 0.4"/>
    </geometry>
    </visual>
  </link>

  <joint name="b_arm_3" type="fixed">
    <parent link="base_link" />
    <child link="arm_3" />
  </joint>

  <link name="arm_4">
    <visual>
    <geometry>
    <box size="0.6 0.2 0.5"/>
    </geometry>
    </visual>
  </link>

  <joint name="b_arm_4" type="fixed">
    <parent link="base_link" />
    <child link="arm_4" />
  </joint>

  <link name="prop_1" />
  <link name="prop_2" />
  <link name="prop_3" />
  <link name="prop_4" />

  <joint name="m_1" type="continuous">
    <parent link="arm_1" />
    <child link="prop_1" />
  </joint>

  <joint name="m_2" type="continuous">
    <parent link="arm_2" />
    <child link="prop_2" />
  </joint>

  <joint name="m_3" type="continuous">
    <parent link="arm_3" />
    <child link="prop_3" />
  </joint>

  <joint name="m_4" type="continuous">
    <parent link="arm_4" />
    <child link="prop_4" />
  </joint>

</robot>
